Workbook

Sheet SUMMARY
A1: OpenDuck Mini V3 ENHANCED - BOM SUMMARY
A3: Project Configuration:
A4: Base Robot + Computer Vision Eyes + Functional 2DOF Arms
A6: COST BREAKDOWN | B6: EUR | C6: Status
A7: 3D Printer (QIDI X-Max 3) | B7: 599 | C7: PURCHASED
A8: Compute & Control | B8: =COMPLETE_BOM!C8 | C8: To Buy
A9: Power System | B9: =COMPLETE_BOM!C17 | C9: To Buy
A10: Servos (Legs) | B10: =COMPLETE_BOM!C27 | C10: To Buy
A11: Sensors & I/O | B11: =COMPLETE_BOM!C33 | C11: To Buy
A12: Computer Vision ADD-ON | B12: =COMPLETE_BOM!C39 | C12: To Buy
A13: Braccia 2DOF ADD-ON | B13: =COMPLETE_BOM!C47 | C13: To Buy
A14: Hardware Meccanico | B14: =COMPLETE_BOM!C54 | C14: To Buy
A15: Filamenti Base | B15: =COMPLETE_BOM!C60 | C15: To Buy
A16: Cavi & Connettori | B16: =COMPLETE_BOM!C69 | C16: To Buy
A17: SUBTOTAL (No Tools) | B17: =SUM(B7:B16)
A18: Tools (Optional) | B18: =COMPLETE_BOM!C76 | C18: Optional
A19: TOTAL WITH TOOLS | B19: =B17+B18
A21: KEY FEATURES:
A22: 3D Printer already purchased (QIDI X-Max 3 @ EUR 599)
A23: 14x STS3215 Smart Servos for bipedal walking
A24: Raspberry Pi AI Camera (IMX500) for computer vision eyes
A25: 2DOF Functional Arms with gripper for object manipulation
A26: Creative rainbow/gradient filaments for unique aesthetics

Sheet COMPLETE_BOM
A1: # | B1: Component | C1: Price | D1: Qty | E1: Total | F1: EU Link | G1: Notes
A2: 1. HARDWARE ALREADY PURCHASED
A3: 1 | B3: 3D Printer: QIDI X-Max 3 | C3: 599 | D3: 1 | E3: =C3*D3 | F3: https://eu.qidi3d.com/products/qidi-x-max-3 | G3: 325x325x315mm, 350C, 65C chamber
A4: ALREADY PURCHASED | E4: =SUM(E3:E3)
A6: 2. COMPUTE & CONTROL
A7: 2 | B7: Raspberry Pi Zero 2W | C7: 26 | D7: 1 | E7: =C7*D7 | F7: https://www.melopero.com/raspberry-pi-zero-2-w | G7: 1GHz quad-core, 512MB RAM
A8: 3 | B8: MicroSD Card 64GB U3 A1 | C8: 12 | D8: 1 | E8: =C8*D8 | F8: https://www.amazon.it/dp/B08GYKNCCP | G8: SanDisk Extreme
A9: 4 | B9: Servo Control Board | C9: 12 | D9: 1 | E9: =C9*D9 | F9: https://www.waveshare.com/servo-driver-hat.htm | G9: Waveshare 16-channel PWM
A10: SUBTOTAL | E10: =SUM(E7:E9)
A12: 3. POWER SYSTEM
A13: 5 | B13: Molicel 18650 P30B 3000mAh 30A | C13: 7 | D13: 2 | E13: =C13*D13 | F13: https://eu.nkon.nl/molicel-inr18650-p30b.html | G13: High discharge rate
A14: 6 | B14: 18650 Dual Cell Holder | C14: 5 | D14: 1 | E14: =C14*D14 | F14: https://www.amazon.it/s?k=18650+dual+cell+holder | G14: With solder tabs
A15: 7 | B15: 2S BMS 7.4V 10A | C15: 9 | D15: 1 | E15: =C15*D15 | F15: https://www.aliexpress.com | G15: Overcurrent protection
A16: 8 | B16: UBEC 5V 5A Step-Down | C16: 12 | D16: 1 | E16: =C16*D16 | F16: https://www.amazon.it/s?k=ubec+5v+5a | G16: Hobbywing or equiv
A17: 9 | B17: Power Switch 10A Rocker | C17: 5 | D17: 1 | E17: =C17*D17 | F17: https://www.amazon.it/s?k=rocker+switch+10a | G17: With LED indicator
A18: 10 | B18: USB-C Charger 5V 3A | C18: 10 | D18: 1 | E18: =C18*D18 | F18: https://www.amazon.it/s?k=usb-c+charger+5v+3a | G18: For 18650 charging
A19: 11 | B19: XT30 Connectors (5 pairs) | C19: 8 | D19: 1 | E19: =C19*D19 | F19: https://www.amazon.it/s?k=xt30+connectors | G19: Male/Female pairs
A20: 12 | B20: LiPo Fireproof Bag | C20: 10 | D20: 1 | E20: =C20*D20 | F20: https://www.amazon.it/s?k=lipo+fireproof+bag | G20: MANDATORY SAFETY
A21: SUBTOTAL | E21: =SUM(E13:E20)
A23: 4. SERVOS (LEGS) - MOST EXPENSIVE
A24: 13 | B24: Feetech STS3215 Servo (7.4V, 19kg-cm) | C24: 18 | D24: 14 | E24: =C24*D24 | F24: https://www.aliexpress.com | G24: Buy 7.4V version, NOT 6V
A25: 14 | B25: 9g Micro Servo SG90 (5-pack) | C25: 6 | D25: 1 | E25: =C25*D25 | F25: https://www.amazon.it/s?k=sg90+servo | G25: For head/accessories
A26: SUBTOTAL | E26: =SUM(E24:E25)
A28: 5. SENSORS & I/O
A29: 15 | B29: BNO055 9-DOF IMU Sensor | C29: 32 | D29: 1 | E29: =C29*D29 | F29: https://www.amazon.it/s?k=bno055 | G29: Adafruit or clone
A30: 16 | B30: Micro Limit Switch SS-10 (20-pack) | C30: 6 | D30: 1 | E30: =C30*D30 | F30: https://www.amazon.it/s?k=micro+limit+switch | G30: For feet contact detection
A31: SUBTOTAL | E31: =SUM(E29:E30)
A33: 6. COMPUTER VISION ADD-ON (Custom)
A34: 17 | B34: Raspberry Pi AI Camera (IMX500) | C34: 70 | D34: 1 | E34: =C34*D34 | F34: https://www.raspberrypi.com/products/ai-camera/ | G34: On-sensor AI, 12MP
A35: 18 | B35: Camera Flex Cable 15cm | C35: 5 | D35: 1 | E35: =C35*D35 | F35: https://www.amazon.it/s?k=raspberry+pi+camera+cable | G35: For mounting in head
A36: 19 | B36: Acrylic Eye Lenses Dome 20mm (2pcs) | C36: 8 | D36: 1 | E36: =C36*D36 | F36: https://www.aliexpress.com | G36: For robot eyes effect
A37: SUBTOTAL | E37: =SUM(E34:E36)
A39: 7. BRACCIA 2DOF ADD-ON (Custom)
A40: 20 | B40: 2DOF Metal Gripper Arm Kit | C40: 25 | D40: 1 | E40: =C40*D40 | F40: https://www.amazon.com/dp/B0FD721PVY | G40: Aluminium, with gripper
A41: 21 | B41: MG90S Metal Gear Servos (4x) | C41: 18 | D41: 1 | E41: =C41*D41 | F41: https://www.amazon.it/s?k=mg90s+servo | G41: 2x shoulder, 2x gripper
A42: 22 | B42: Servo Extension Cables 30cm (10pcs) | C42: 8 | D42: 1 | E42: =C42*D42 | F42: https://www.amazon.it/s?k=servo+extension+cable | G42: For arm wiring
A43: SUBTOTAL | E43: =SUM(E40:E42)
A45: 8. HARDWARE MECCANICO
A46: 23 | B46: M3 Heat-Set Inserts (100pcs) | C46: 8 | D46: 1 | E46: =C46*D46 | F46: https://www.amazon.it/s?k=m3+heat+set+inserts | G46: M3x5mm for 3D prints
A47: 24 | B47: M2/M3 Screw Assortment (600pcs) | C47: 12 | D47: 1 | E47: =C47*D47 | F47: https://www.amazon.it/s?k=m2+m3+screw+kit | G47: Various lengths
...

Sheet FILAMENTS_CREATIVE
A1: CREATIVE FILAMENTS - Rainbow, Gradient & Multicolor
A3: Filament Type | B3: Price | C3: Color Effect | D3: EU Link | E3: Best For
A4: SUNLU Rainbow PLA+ 1kg | B4: 23 | C4: Gradient every 8m (Red-Cyan-Blue-Purple) | D4: https://www.amazon.it/dp/B0CHWDSQ7H | E4: OpenDuck body, drone frames
A5: SUNLU Silk Rainbow PLA+ 1kg | B5: 25 | C5: Silky gradient (Lilac-Violet) | D5: https://www.amazon.it/dp/B0DFBQDT78 | E5: Premium glossy finish, display pieces
A6: SUNLU Transparent Rainbow PLA 1kg | B6: 24 | C6: Translucent gradient colors | D6: https://www.amazon.it/dp/B0FPM97CNK | E6: Light-through effects, artistic
A7: Sovol Rainbow Matte PLA 1kg | B7: 22 | C7: Matte finish gradient | D7: https://www.amazon.it/dp/B0DB84Z3ZT | E7: Modern matte aesthetic, vases
A8: SUNLU Rainbow PETG 1kg | B8: 26 | C8: Stronger rainbow gradient | D8: https://www.amazon.com/dp/B0DM871XFF | E8: Functional parts, outdoor use
A9: eSUN PLA+ Rainbow 1kg | B9: 24 | C9: Fast color change | D9: https://www.amazon.it/s?k=esun+pla+rainbow | E9: Multi-project spool
A10: Polymaker PolyTerra Matte Rainbow | B10: 21 | C10: Eco-friendly matte | D10: https://www.amazon.it/s?k=polymaker+rainbow | E10: Sustainable choice, indoor decor
A11: Creality Hyper Rainbow PLA 1kg | B11: 20 | C11: Budget rainbow option | D11: https://www.amazon.it/s?k=creality+hyper+pla | E11: Testing, prototypes
A13: RECOMMENDATION:
A14: SUNLU Rainbow PLA+ (Best value, vibrant colors)
A15: SUNLU Silk Rainbow (Premium glossy finish)
A16: Sovol Matte Rainbow (Modern aesthetic)
A18: TIPS:
A19: Color changes every 8-16 meters depending on brand
A20: Use rainbow for body parts to avoid manual color changes
A21: Mix white PLA for structure + rainbow for visible parts
A22: PETG rainbow for drone frames (stronger + UV resistant)
